<?xml version="1.0"?>
<robot xmlns:xacro="http://ros.org/wiki/xacro" name="robot_car">

  <material name="blue">
    <color rgba="0 0 1 1"/> <!-- 藍色 -->
  </material>

  <material name="red">
    <color rgba="1 0 0 1"/> <!-- 紅色 -->
  </material>
  
  <!-- 車體 -->
  <link name="base_link">
    <visual>
      <geometry>
        <box size="0.4 0.2 0.1"/>
      </geometry>
      <material name="blue"/>
    </visual>
  </link>

  <!-- 輪子 -->
  <xacro:macro name="wheel" params="name">
    <link name="${name}">
      <visual>
        <geometry>
          <cylinder radius="0.05" length="0.02"/>
        </geometry>
        <material name="black"/>
      </visual>
    </link>
    <joint name="${name}_joint" type="continuous">
      <parent link="base_link"/>
      <child link="${name}"/>
      <origin xyz="0 0 0" rpy="0 0 0"/>
      <axis xyz="0 0 1"/>
    </joint>
  </xacro:macro>

  <xacro:wheel name="front_left_wheel"/>
  <xacro:wheel name="front_right_wheel"/>
  <xacro:wheel name="rear_left_wheel"/>
  <xacro:wheel name="rear_right_wheel"/>

  <!-- 發射器 -->
  <link name="launcher">
    <visual>
      <geometry>
        <cylinder radius="0.03" length="0.2"/>
      </geometry>
      <material name="red"/>
    </visual>
  </link>
  <joint name="launcher_joint" type="fixed">
    <parent link="base_link"/>
    <child link="launcher"/>
    <origin xyz="0 0.1 0.1" rpy="0 0 0"/>
  </joint>

</robot>